Invalid HTTP_HOST header: '127.0.0.1:8000'. You may need to add '127.0.0.1' to ALLOWED_HOSTS.
Traceback (most recent call last):
  File "F:\Project\Ignite\backend\env\Lib\site-packages\django\core\handlers\exception.py", line 55, in inner
    response = get_response(request)
               ^^^^^^^^^^^^^^^^^^^^^
  File "F:\Project\Ignite\backend\env\Lib\site-packages\django\utils\deprecation.py", line 128, in __call__
    response = self.process_request(request)
               ^^^^^^^^^^^^^^^^^^^^^^^^^^^^^
  File "F:\Project\Ignite\backend\env\Lib\site-packages\django\middleware\common.py", line 48, in process_request
    host = request.get_host()
           ^^^^^^^^^^^^^^^^^^
  File "F:\Project\Ignite\backend\env\Lib\site-packages\django\http\request.py", line 151, in get_host
    raise DisallowedHost(msg)
django.core.exceptions.DisallowedHost: Invalid HTTP_HOST header: '127.0.0.1:8000'. You may need to add '127.0.0.1' to ALLOWED_HOSTS.
Internal Server Error: /payment/
Traceback (most recent call last):
  File "F:\Project\Ignite\backend\env\Lib\site-packages\django\core\handlers\exception.py", line 55, in inner
    response = get_response(request)
               ^^^^^^^^^^^^^^^^^^^^^
  File "F:\Project\Ignite\backend\env\Lib\site-packages\django\core\handlers\base.py", line 197, in _get_response
    response = wrapped_callback(request, *callback_args, **callback_kwargs)
               ^^^^^^^^^^^^^^^^^^^^^^^^^^^^^^^^^^^^^^^^^^^^^^^^^^^^^^^^^^^^
  File "F:\Project\Ignite\backend\ignite_backend\Home\views.py", line 86, in payment
    "orderId": f"order_{entry.id}_{int(time.time())}",
                                       ^^^^
NameError: name 'time' is not defined
"GET /payment/?entry_id=38 HTTP/1.1" 500 74725
Internal Server Error: /payment/
Traceback (most recent call last):
  File "F:\Project\Ignite\backend\env\Lib\site-packages\urllib3\connection.py", line 198, in _new_conn
    sock = connection.create_connection(
           ^^^^^^^^^^^^^^^^^^^^^^^^^^^^^
  File "F:\Project\Ignite\backend\env\Lib\site-packages\urllib3\util\connection.py", line 60, in create_connection
    for res in socket.getaddrinfo(host, port, family, socket.SOCK_STREAM):
               ^^^^^^^^^^^^^^^^^^^^^^^^^^^^^^^^^^^^^^^^^^^^^^^^^^^^^^^^^^
  File "C:\Users\Acer\AppData\Local\Programs\Python\Python311\Lib\socket.py", line 962, in getaddrinfo
    for res in _socket.getaddrinfo(host, port, family, type, proto, flags):
               ^^^^^^^^^^^^^^^^^^^^^^^^^^^^^^^^^^^^^^^^^^^^^^^^^^^^^^^^^^^
socket.gaierror: [Errno 11001] getaddrinfo failed

The above exception was the direct cause of the following exception:

Traceback (most recent call last):
  File "F:\Project\Ignite\backend\env\Lib\site-packages\urllib3\connectionpool.py", line 787, in urlopen
    response = self._make_request(
               ^^^^^^^^^^^^^^^^^^^
  File "F:\Project\Ignite\backend\env\Lib\site-packages\urllib3\connectionpool.py", line 488, in _make_request
    raise new_e
  File "F:\Project\Ignite\backend\env\Lib\site-packages\urllib3\connectionpool.py", line 464, in _make_request
    self._validate_conn(conn)
  File "F:\Project\Ignite\backend\env\Lib\site-packages\urllib3\connectionpool.py", line 1093, in _validate_conn
    conn.connect()
  File "F:\Project\Ignite\backend\env\Lib\site-packages\urllib3\connection.py", line 704, in connect
    self.sock = sock = self._new_conn()
                       ^^^^^^^^^^^^^^^^
  File "F:\Project\Ignite\backend\env\Lib\site-packages\urllib3\connection.py", line 205, in _new_conn
    raise NameResolutionError(self.host, self, e) from e
urllib3.exceptions.NameResolutionError: <urllib3.connection.HTTPSConnection object at 0x0000017D7D53AED0>: Failed to resolve 'api.razorpay.com' ([Errno 11001] getaddrinfo failed)

The above exception was the direct cause of the following exception:

Traceback (most recent call last):
  File "F:\Project\Ignite\backend\env\Lib\site-packages\requests\adapters.py", line 667, in send
    resp = conn.urlopen(
           ^^^^^^^^^^^^^
  File "F:\Project\Ignite\backend\env\Lib\site-packages\urllib3\connectionpool.py", line 841, in urlopen
    retries = retries.increment(
              ^^^^^^^^^^^^^^^^^^
  File "F:\Project\Ignite\backend\env\Lib\site-packages\urllib3\util\retry.py", line 519, in increment
    raise MaxRetryError(_pool, url, reason) from reason  # type: ignore[arg-type]
    ^^^^^^^^^^^^^^^^^^^^^^^^^^^^^^^^^^^^^^^^^^^^^^^^^^^
urllib3.exceptions.MaxRetryError: HTTPSConnectionPool(host='api.razorpay.com', port=443): Max retries exceeded with url: /v1/orders (Caused by NameResolutionError("<urllib3.connection.HTTPSConnection object at 0x0000017D7D53AED0>: Failed to resolve 'api.razorpay.com' ([Errno 11001] getaddrinfo failed)"))

During handling of the above exception, another exception occurred:

Traceback (most recent call last):
  File "F:\Project\Ignite\backend\env\Lib\site-packages\django\core\handlers\exception.py", line 55, in inner
    response = get_response(request)
               ^^^^^^^^^^^^^^^^^^^^^
  File "F:\Project\Ignite\backend\env\Lib\site-packages\django\core\handlers\base.py", line 197, in _get_response
    response = wrapped_callback(request, *callback_args, **callback_kwargs)
               ^^^^^^^^^^^^^^^^^^^^^^^^^^^^^^^^^^^^^^^^^^^^^^^^^^^^^^^^^^^^
  File "F:\Project\Ignite\backend\ignite_backend\Home\views.py", line 75, in payment
    order = client.order.create(data=order_data)
            ^^^^^^^^^^^^^^^^^^^^^^^^^^^^^^^^^^^^
  File "F:\Project\Ignite\backend\env\Lib\site-packages\razorpay\resources\order.py", line 71, in create
    return self.post_url(url, data, **kwargs)
           ^^^^^^^^^^^^^^^^^^^^^^^^^^^^^^^^^^
  File "F:\Project\Ignite\backend\env\Lib\site-packages\razorpay\resources\base.py", line 20, in post_url
    return self.client.post(url, data, **kwargs)
           ^^^^^^^^^^^^^^^^^^^^^^^^^^^^^^^^^^^^^
  File "F:\Project\Ignite\backend\env\Lib\site-packages\razorpay\client.py", line 156, in post
    return self.request('post', path, data=data, **options)
           ^^^^^^^^^^^^^^^^^^^^^^^^^^^^^^^^^^^^^^^^^^^^^^^^
  File "F:\Project\Ignite\backend\env\Lib\site-packages\razorpay\client.py", line 120, in request
    response = getattr(self.session, method)(url, auth=self.auth,
               ^^^^^^^^^^^^^^^^^^^^^^^^^^^^^^^^^^^^^^^^^^^^^^^^^^
  File "F:\Project\Ignite\backend\env\Lib\site-packages\requests\sessions.py", line 637, in post
    return self.request("POST", url, data=data, json=json, **kwargs)
           ^^^^^^^^^^^^^^^^^^^^^^^^^^^^^^^^^^^^^^^^^^^^^^^^^^^^^^^^^
  File "F:\Project\Ignite\backend\env\Lib\site-packages\requests\sessions.py", line 589, in request
    resp = self.send(prep, **send_kwargs)
           ^^^^^^^^^^^^^^^^^^^^^^^^^^^^^^
  File "F:\Project\Ignite\backend\env\Lib\site-packages\requests\sessions.py", line 703, in send
    r = adapter.send(request, **kwargs)
        ^^^^^^^^^^^^^^^^^^^^^^^^^^^^^^^
  File "F:\Project\Ignite\backend\env\Lib\site-packages\requests\adapters.py", line 700, in send
    raise ConnectionError(e, request=request)
requests.exceptions.ConnectionError: HTTPSConnectionPool(host='api.razorpay.com', port=443): Max retries exceeded with url: /v1/orders (Caused by NameResolutionError("<urllib3.connection.HTTPSConnection object at 0x0000017D7D53AED0>: Failed to resolve 'api.razorpay.com' ([Errno 11001] getaddrinfo failed)"))
"GET /payment/?entry_id=38 HTTP/1.1" 500 188886
Internal Server Error: /payment/
Traceback (most recent call last):
  File "F:\Project\Ignite\backend\env\Lib\site-packages\urllib3\connection.py", line 198, in _new_conn
    sock = connection.create_connection(
           ^^^^^^^^^^^^^^^^^^^^^^^^^^^^^
  File "F:\Project\Ignite\backend\env\Lib\site-packages\urllib3\util\connection.py", line 60, in create_connection
    for res in socket.getaddrinfo(host, port, family, socket.SOCK_STREAM):
               ^^^^^^^^^^^^^^^^^^^^^^^^^^^^^^^^^^^^^^^^^^^^^^^^^^^^^^^^^^
  File "C:\Users\Acer\AppData\Local\Programs\Python\Python311\Lib\socket.py", line 962, in getaddrinfo
    for res in _socket.getaddrinfo(host, port, family, type, proto, flags):
               ^^^^^^^^^^^^^^^^^^^^^^^^^^^^^^^^^^^^^^^^^^^^^^^^^^^^^^^^^^^
socket.gaierror: [Errno 11001] getaddrinfo failed

The above exception was the direct cause of the following exception:

Traceback (most recent call last):
  File "F:\Project\Ignite\backend\env\Lib\site-packages\urllib3\connectionpool.py", line 787, in urlopen
    response = self._make_request(
               ^^^^^^^^^^^^^^^^^^^
  File "F:\Project\Ignite\backend\env\Lib\site-packages\urllib3\connectionpool.py", line 488, in _make_request
    raise new_e
  File "F:\Project\Ignite\backend\env\Lib\site-packages\urllib3\connectionpool.py", line 464, in _make_request
    self._validate_conn(conn)
  File "F:\Project\Ignite\backend\env\Lib\site-packages\urllib3\connectionpool.py", line 1093, in _validate_conn
    conn.connect()
  File "F:\Project\Ignite\backend\env\Lib\site-packages\urllib3\connection.py", line 704, in connect
    self.sock = sock = self._new_conn()
                       ^^^^^^^^^^^^^^^^
  File "F:\Project\Ignite\backend\env\Lib\site-packages\urllib3\connection.py", line 205, in _new_conn
    raise NameResolutionError(self.host, self, e) from e
urllib3.exceptions.NameResolutionError: <urllib3.connection.HTTPSConnection object at 0x0000017D7E7429D0>: Failed to resolve 'api.razorpay.com' ([Errno 11001] getaddrinfo failed)

The above exception was the direct cause of the following exception:

Traceback (most recent call last):
  File "F:\Project\Ignite\backend\env\Lib\site-packages\requests\adapters.py", line 667, in send
    resp = conn.urlopen(
           ^^^^^^^^^^^^^
  File "F:\Project\Ignite\backend\env\Lib\site-packages\urllib3\connectionpool.py", line 841, in urlopen
    retries = retries.increment(
              ^^^^^^^^^^^^^^^^^^
  File "F:\Project\Ignite\backend\env\Lib\site-packages\urllib3\util\retry.py", line 519, in increment
    raise MaxRetryError(_pool, url, reason) from reason  # type: ignore[arg-type]
    ^^^^^^^^^^^^^^^^^^^^^^^^^^^^^^^^^^^^^^^^^^^^^^^^^^^
urllib3.exceptions.MaxRetryError: HTTPSConnectionPool(host='api.razorpay.com', port=443): Max retries exceeded with url: /v1/orders (Caused by NameResolutionError("<urllib3.connection.HTTPSConnection object at 0x0000017D7E7429D0>: Failed to resolve 'api.razorpay.com' ([Errno 11001] getaddrinfo failed)"))

During handling of the above exception, another exception occurred:

Traceback (most recent call last):
  File "F:\Project\Ignite\backend\env\Lib\site-packages\django\core\handlers\exception.py", line 55, in inner
    response = get_response(request)
               ^^^^^^^^^^^^^^^^^^^^^
  File "F:\Project\Ignite\backend\env\Lib\site-packages\django\core\handlers\base.py", line 197, in _get_response
    response = wrapped_callback(request, *callback_args, **callback_kwargs)
               ^^^^^^^^^^^^^^^^^^^^^^^^^^^^^^^^^^^^^^^^^^^^^^^^^^^^^^^^^^^^
  File "F:\Project\Ignite\backend\ignite_backend\Home\views.py", line 75, in payment
    order = client.order.create(data=order_data)
            ^^^^^^^^^^^^^^^^^^^^^^^^^^^^^^^^^^^^
  File "F:\Project\Ignite\backend\env\Lib\site-packages\razorpay\resources\order.py", line 71, in create
    return self.post_url(url, data, **kwargs)
           ^^^^^^^^^^^^^^^^^^^^^^^^^^^^^^^^^^
  File "F:\Project\Ignite\backend\env\Lib\site-packages\razorpay\resources\base.py", line 20, in post_url
    return self.client.post(url, data, **kwargs)
           ^^^^^^^^^^^^^^^^^^^^^^^^^^^^^^^^^^^^^
  File "F:\Project\Ignite\backend\env\Lib\site-packages\razorpay\client.py", line 156, in post
    return self.request('post', path, data=data, **options)
           ^^^^^^^^^^^^^^^^^^^^^^^^^^^^^^^^^^^^^^^^^^^^^^^^
  File "F:\Project\Ignite\backend\env\Lib\site-packages\razorpay\client.py", line 120, in request
    response = getattr(self.session, method)(url, auth=self.auth,
               ^^^^^^^^^^^^^^^^^^^^^^^^^^^^^^^^^^^^^^^^^^^^^^^^^^
  File "F:\Project\Ignite\backend\env\Lib\site-packages\requests\sessions.py", line 637, in post
    return self.request("POST", url, data=data, json=json, **kwargs)
           ^^^^^^^^^^^^^^^^^^^^^^^^^^^^^^^^^^^^^^^^^^^^^^^^^^^^^^^^^
  File "F:\Project\Ignite\backend\env\Lib\site-packages\requests\sessions.py", line 589, in request
    resp = self.send(prep, **send_kwargs)
           ^^^^^^^^^^^^^^^^^^^^^^^^^^^^^^
  File "F:\Project\Ignite\backend\env\Lib\site-packages\requests\sessions.py", line 703, in send
    r = adapter.send(request, **kwargs)
        ^^^^^^^^^^^^^^^^^^^^^^^^^^^^^^^
  File "F:\Project\Ignite\backend\env\Lib\site-packages\requests\adapters.py", line 700, in send
    raise ConnectionError(e, request=request)
requests.exceptions.ConnectionError: HTTPSConnectionPool(host='api.razorpay.com', port=443): Max retries exceeded with url: /v1/orders (Caused by NameResolutionError("<urllib3.connection.HTTPSConnection object at 0x0000017D7E7429D0>: Failed to resolve 'api.razorpay.com' ([Errno 11001] getaddrinfo failed)"))
"GET /payment/?entry_id=38 HTTP/1.1" 500 189396
Internal Server Error: /payment/
Traceback (most recent call last):
  File "F:\Project\Ignite\backend\env\Lib\site-packages\urllib3\connection.py", line 198, in _new_conn
    sock = connection.create_connection(
           ^^^^^^^^^^^^^^^^^^^^^^^^^^^^^
  File "F:\Project\Ignite\backend\env\Lib\site-packages\urllib3\util\connection.py", line 60, in create_connection
    for res in socket.getaddrinfo(host, port, family, socket.SOCK_STREAM):
               ^^^^^^^^^^^^^^^^^^^^^^^^^^^^^^^^^^^^^^^^^^^^^^^^^^^^^^^^^^
  File "C:\Users\Acer\AppData\Local\Programs\Python\Python311\Lib\socket.py", line 962, in getaddrinfo
    for res in _socket.getaddrinfo(host, port, family, type, proto, flags):
               ^^^^^^^^^^^^^^^^^^^^^^^^^^^^^^^^^^^^^^^^^^^^^^^^^^^^^^^^^^^
socket.gaierror: [Errno 11001] getaddrinfo failed

The above exception was the direct cause of the following exception:

Traceback (most recent call last):
  File "F:\Project\Ignite\backend\env\Lib\site-packages\urllib3\connectionpool.py", line 787, in urlopen
    response = self._make_request(
               ^^^^^^^^^^^^^^^^^^^
  File "F:\Project\Ignite\backend\env\Lib\site-packages\urllib3\connectionpool.py", line 488, in _make_request
    raise new_e
  File "F:\Project\Ignite\backend\env\Lib\site-packages\urllib3\connectionpool.py", line 464, in _make_request
    self._validate_conn(conn)
  File "F:\Project\Ignite\backend\env\Lib\site-packages\urllib3\connectionpool.py", line 1093, in _validate_conn
    conn.connect()
  File "F:\Project\Ignite\backend\env\Lib\site-packages\urllib3\connection.py", line 704, in connect
    self.sock = sock = self._new_conn()
                       ^^^^^^^^^^^^^^^^
  File "F:\Project\Ignite\backend\env\Lib\site-packages\urllib3\connection.py", line 205, in _new_conn
    raise NameResolutionError(self.host, self, e) from e
urllib3.exceptions.NameResolutionError: <urllib3.connection.HTTPSConnection object at 0x0000017D7D3E46D0>: Failed to resolve 'api.razorpay.com' ([Errno 11001] getaddrinfo failed)

The above exception was the direct cause of the following exception:

Traceback (most recent call last):
  File "F:\Project\Ignite\backend\env\Lib\site-packages\requests\adapters.py", line 667, in send
    resp = conn.urlopen(
           ^^^^^^^^^^^^^
  File "F:\Project\Ignite\backend\env\Lib\site-packages\urllib3\connectionpool.py", line 841, in urlopen
    retries = retries.increment(
              ^^^^^^^^^^^^^^^^^^
  File "F:\Project\Ignite\backend\env\Lib\site-packages\urllib3\util\retry.py", line 519, in increment
    raise MaxRetryError(_pool, url, reason) from reason  # type: ignore[arg-type]
    ^^^^^^^^^^^^^^^^^^^^^^^^^^^^^^^^^^^^^^^^^^^^^^^^^^^
urllib3.exceptions.MaxRetryError: HTTPSConnectionPool(host='api.razorpay.com', port=443): Max retries exceeded with url: /v1/orders (Caused by NameResolutionError("<urllib3.connection.HTTPSConnection object at 0x0000017D7D3E46D0>: Failed to resolve 'api.razorpay.com' ([Errno 11001] getaddrinfo failed)"))

During handling of the above exception, another exception occurred:

Traceback (most recent call last):
  File "F:\Project\Ignite\backend\env\Lib\site-packages\django\core\handlers\exception.py", line 55, in inner
    response = get_response(request)
               ^^^^^^^^^^^^^^^^^^^^^
  File "F:\Project\Ignite\backend\env\Lib\site-packages\django\core\handlers\base.py", line 197, in _get_response
    response = wrapped_callback(request, *callback_args, **callback_kwargs)
               ^^^^^^^^^^^^^^^^^^^^^^^^^^^^^^^^^^^^^^^^^^^^^^^^^^^^^^^^^^^^
  File "F:\Project\Ignite\backend\ignite_backend\Home\views.py", line 75, in payment
    order = client.order.create(data=order_data)
            ^^^^^^^^^^^^^^^^^^^^^^^^^^^^^^^^^^^^
  File "F:\Project\Ignite\backend\env\Lib\site-packages\razorpay\resources\order.py", line 71, in create
    return self.post_url(url, data, **kwargs)
           ^^^^^^^^^^^^^^^^^^^^^^^^^^^^^^^^^^
  File "F:\Project\Ignite\backend\env\Lib\site-packages\razorpay\resources\base.py", line 20, in post_url
    return self.client.post(url, data, **kwargs)
           ^^^^^^^^^^^^^^^^^^^^^^^^^^^^^^^^^^^^^
  File "F:\Project\Ignite\backend\env\Lib\site-packages\razorpay\client.py", line 156, in post
    return self.request('post', path, data=data, **options)
           ^^^^^^^^^^^^^^^^^^^^^^^^^^^^^^^^^^^^^^^^^^^^^^^^
  File "F:\Project\Ignite\backend\env\Lib\site-packages\razorpay\client.py", line 120, in request
    response = getattr(self.session, method)(url, auth=self.auth,
               ^^^^^^^^^^^^^^^^^^^^^^^^^^^^^^^^^^^^^^^^^^^^^^^^^^
  File "F:\Project\Ignite\backend\env\Lib\site-packages\requests\sessions.py", line 637, in post
    return self.request("POST", url, data=data, json=json, **kwargs)
           ^^^^^^^^^^^^^^^^^^^^^^^^^^^^^^^^^^^^^^^^^^^^^^^^^^^^^^^^^
  File "F:\Project\Ignite\backend\env\Lib\site-packages\requests\sessions.py", line 589, in request
    resp = self.send(prep, **send_kwargs)
           ^^^^^^^^^^^^^^^^^^^^^^^^^^^^^^
  File "F:\Project\Ignite\backend\env\Lib\site-packages\requests\sessions.py", line 703, in send
    r = adapter.send(request, **kwargs)
        ^^^^^^^^^^^^^^^^^^^^^^^^^^^^^^^
  File "F:\Project\Ignite\backend\env\Lib\site-packages\requests\adapters.py", line 700, in send
    raise ConnectionError(e, request=request)
requests.exceptions.ConnectionError: HTTPSConnectionPool(host='api.razorpay.com', port=443): Max retries exceeded with url: /v1/orders (Caused by NameResolutionError("<urllib3.connection.HTTPSConnection object at 0x0000017D7D3E46D0>: Failed to resolve 'api.razorpay.com' ([Errno 11001] getaddrinfo failed)"))
